def get_some_sum(some_arg):
    try:
        result = some_arg[0] + 2
    # перехватываем исключение и сохраняем его в переменную
    except TypeError as e:
        # выводим результат обработки на экран. Вместо этого можно
        # производить логирование
        print(len(some_arg[0]) + 2)
        # принудительно вызываем ту же ошибку, что получили ранее
        raise e

# В случае передачи строки будет вызвано исключение TypeError.
# Мы обработаем его и выведем результат на экран, однако после этого снова
# вызовем то же самое исключение, и программа завершит свою работу
print(get_some_sum('это строка'))